03/08/20 (13:13:36) | ERROR: Data collection thread failed with exception: not sure how to interpret line '   8       0 sda 39772 8790 17646155 60441 14708 12829 24384568 99562 0 57380 160270 0 0 0 0 220 267\n'
Traceback (most recent call last):
  File "/usr/local/bin/bpytop", line 2315, in _runner
    collector._collect()
  File "/usr/local/bin/bpytop", line 2578, in _collect
    io_counters = psutil.disk_io_counters(perdisk=True if SYSTEM == "Linux" else False, nowrap=True)
  File "/home/aethan/anaconda3/lib/python3.7/site-packages/psutil/__init__.py", line 2168, in disk_io_counters
    rawdict = _psplatform.disk_io_counters(**kwargs)
  File "/home/aethan/anaconda3/lib/python3.7/site-packages/psutil/_pslinux.py", line 1125, in disk_io_counters
    for entry in gen:
  File "/home/aethan/anaconda3/lib/python3.7/site-packages/psutil/_pslinux.py", line 1098, in read_procfs
    raise ValueError("not sure how to interpret line %r" % line)
ValueError: not sure how to interpret line '   8       0 sda 39772 8790 17646155 60441 14708 12829 24384568 99562 0 57380 160270 0 0 0 0 220 267\n'
03/08/20 (13:13:36) | WARNING: Exiting with errorcode (1). Runtime 0:00:03 

03/08/20 (13:13:45) | ERROR: Data collection thread failed with exception: not sure how to interpret line '   8       0 sda 39772 8790 17646155 60441 14708 12829 24384568 99562 0 57380 160270 0 0 0 0 220 267\n'
Traceback (most recent call last):
  File "/usr/local/bin/bpytop", line 2315, in _runner
    collector._collect()
  File "/usr/local/bin/bpytop", line 2578, in _collect
    io_counters = psutil.disk_io_counters(perdisk=True if SYSTEM == "Linux" else False, nowrap=True)
  File "/home/aethan/anaconda3/lib/python3.7/site-packages/psutil/__init__.py", line 2168, in disk_io_counters
    rawdict = _psplatform.disk_io_counters(**kwargs)
  File "/home/aethan/anaconda3/lib/python3.7/site-packages/psutil/_pslinux.py", line 1125, in disk_io_counters
    for entry in gen:
  File "/home/aethan/anaconda3/lib/python3.7/site-packages/psutil/_pslinux.py", line 1098, in read_procfs
    raise ValueError("not sure how to interpret line %r" % line)
ValueError: not sure how to interpret line '   8       0 sda 39772 8790 17646155 60441 14708 12829 24384568 99562 0 57380 160270 0 0 0 0 220 267\n'
03/08/20 (13:13:45) | WARNING: Exiting with errorcode (1). Runtime 0:00:03 

03/08/20 (13:17:53) | ERROR: Data collection thread failed with exception: not sure how to interpret line '   8       0 sda 39772 8790 17646155 60441 14708 12829 24384568 99562 0 57380 160270 0 0 0 0 220 267\n'
Traceback (most recent call last):
  File "/usr/local/bin/bpytop", line 2315, in _runner
    collector._collect()
  File "/usr/local/bin/bpytop", line 2578, in _collect
    io_counters = psutil.disk_io_counters(perdisk=True if SYSTEM == "Linux" else False, nowrap=True)
  File "/home/aethan/anaconda3/lib/python3.7/site-packages/psutil/__init__.py", line 2168, in disk_io_counters
    rawdict = _psplatform.disk_io_counters(**kwargs)
  File "/home/aethan/anaconda3/lib/python3.7/site-packages/psutil/_pslinux.py", line 1125, in disk_io_counters
    for entry in gen:
  File "/home/aethan/anaconda3/lib/python3.7/site-packages/psutil/_pslinux.py", line 1098, in read_procfs
    raise ValueError("not sure how to interpret line %r" % line)
ValueError: not sure how to interpret line '   8       0 sda 39772 8790 17646155 60441 14708 12829 24384568 99562 0 57380 160270 0 0 0 0 220 267\n'
03/08/20 (13:17:53) | WARNING: Exiting with errorcode (1). Runtime 0:00:03 

03/08/20 (13:19:25) | ERROR: Data collection thread failed with exception: not sure how to interpret line '   8       0 sda 39772 8790 17646155 60441 14708 12829 24384568 99562 0 57380 160270 0 0 0 0 220 267\n'
Traceback (most recent call last):
  File "/usr/local/bin/bpytop", line 2315, in _runner
    collector._collect()
  File "/usr/local/bin/bpytop", line 2578, in _collect
    io_counters = psutil.disk_io_counters(perdisk=True if SYSTEM == "Linux" else False, nowrap=True)
  File "/home/aethan/anaconda3/lib/python3.7/site-packages/psutil/__init__.py", line 2168, in disk_io_counters
    rawdict = _psplatform.disk_io_counters(**kwargs)
  File "/home/aethan/anaconda3/lib/python3.7/site-packages/psutil/_pslinux.py", line 1125, in disk_io_counters
    for entry in gen:
  File "/home/aethan/anaconda3/lib/python3.7/site-packages/psutil/_pslinux.py", line 1098, in read_procfs
    raise ValueError("not sure how to interpret line %r" % line)
ValueError: not sure how to interpret line '   8       0 sda 39772 8790 17646155 60441 14708 12829 24384568 99562 0 57380 160270 0 0 0 0 220 267\n'
03/08/20 (13:19:26) | WARNING: Exiting with errorcode (1). Runtime 0:00:03 

23/08/20 (15:51:56) | WARNING: No theme named "+dracula" found!
04/05/21 (18:17:10) | ERROR: Data collection thread failed with exception: invalid attr name 'io_counters'
Traceback (most recent call last):
  File "/usr/bin/bpytop", line 2931, in _runner
    collector._collect()
  File "/usr/bin/bpytop", line 3767, in _collect
    cls.details = det.as_dict(attrs=attrs, ad_value="")
  File "/usr/lib/python3.9/site-packages/psutil/__init__.py", line 512, in as_dict
    raise ValueError("invalid attr name%s %s" % (
ValueError: invalid attr name 'io_counters'
04/05/21 (18:17:12) | WARNING: Exiting with errorcode (1). Runtime 0:00:06 

31/05/21 (17:04:38) | ERROR: Data collection thread failed with exception: invalid attr name 'io_counters'
Traceback (most recent call last):
  File "/usr/bin/bpytop", line 2931, in _runner
    collector._collect()
  File "/usr/bin/bpytop", line 3767, in _collect
    cls.details = det.as_dict(attrs=attrs, ad_value="")
  File "/usr/lib/python3.9/site-packages/psutil/__init__.py", line 512, in as_dict
    raise ValueError("invalid attr name%s %s" % (
ValueError: invalid attr name 'io_counters'
31/05/21 (17:04:39) | WARNING: Exiting with errorcode (1). Runtime 0:00:21 

31/05/21 (17:09:05) | ERROR: Data collection thread failed with exception: invalid attr name 'io_counters'
Traceback (most recent call last):
  File "/usr/bin/bpytop", line 2931, in _runner
    collector._collect()
  File "/usr/bin/bpytop", line 3767, in _collect
    cls.details = det.as_dict(attrs=attrs, ad_value="")
  File "/usr/lib/python3.9/site-packages/psutil/__init__.py", line 512, in as_dict
    raise ValueError("invalid attr name%s %s" % (
ValueError: invalid attr name 'io_counters'
31/05/21 (17:09:05) | WARNING: Exiting with errorcode (1). Runtime 0:04:20 

31/05/21 (17:09:24) | ERROR: Data collection thread failed with exception: invalid attr name 'io_counters'
Traceback (most recent call last):
  File "/usr/bin/bpytop", line 2931, in _runner
    collector._collect()
  File "/usr/bin/bpytop", line 3767, in _collect
    cls.details = det.as_dict(attrs=attrs, ad_value="")
  File "/usr/lib/python3.9/site-packages/psutil/__init__.py", line 512, in as_dict
    raise ValueError("invalid attr name%s %s" % (
ValueError: invalid attr name 'io_counters'
31/05/21 (17:09:26) | WARNING: Exiting with errorcode (1). Runtime 0:00:18 

31/05/21 (17:10:01) | ERROR: Data collection thread failed with exception: invalid attr name 'io_counters'
Traceback (most recent call last):
  File "/usr/bin/bpytop", line 2931, in _runner
    collector._collect()
  File "/usr/bin/bpytop", line 3767, in _collect
    cls.details = det.as_dict(attrs=attrs, ad_value="")
  File "/usr/lib/python3.9/site-packages/psutil/__init__.py", line 512, in as_dict
    raise ValueError("invalid attr name%s %s" % (
ValueError: invalid attr name 'io_counters'
31/05/21 (17:10:03) | WARNING: Exiting with errorcode (1). Runtime 0:00:34 

05/07/21 (16:38:54) | ERROR: Data collection thread failed with exception: invalid attr name 'io_counters'
Traceback (most recent call last):
  File "/usr/bin/bpytop", line 2938, in _runner
    collector._collect()
  File "/usr/bin/bpytop", line 3775, in _collect
    cls.details = det.as_dict(attrs=attrs, ad_value="")
  File "/usr/lib/python3.9/site-packages/psutil/__init__.py", line 512, in as_dict
    raise ValueError("invalid attr name%s %s" % (
ValueError: invalid attr name 'io_counters'
05/07/21 (16:38:54) | WARNING: Exiting with errorcode (1). Runtime 0:00:42 

01/10/21 (12:52:41) | ERROR: Exception when sending signal 9 to pid 580
01/10/21 (12:52:41) | ERROR: [Errno 1] Operation not permitted
Traceback (most recent call last):
  File "/usr/bin/bpytop", line 5459, in process_keys
    os.kill(pid, sig)
PermissionError: [Errno 1] Operation not permitted
01/10/21 (12:52:49) | ERROR: Exception when sending signal 15 to pid 503
01/10/21 (12:52:49) | ERROR: [Errno 1] Operation not permitted
Traceback (most recent call last):
  File "/usr/bin/bpytop", line 5459, in process_keys
    os.kill(pid, sig)
PermissionError: [Errno 1] Operation not permitted
01/10/21 (12:53:02) | ERROR: Exception when sending signal 9 to pid 503
01/10/21 (12:53:02) | ERROR: [Errno 1] Operation not permitted
Traceback (most recent call last):
  File "/usr/bin/bpytop", line 5459, in process_keys
    os.kill(pid, sig)
PermissionError: [Errno 1] Operation not permitted
01/10/21 (12:53:12) | ERROR: Data collection thread failed with exception: invalid attr name 'io_counters'
Traceback (most recent call last):
  File "/usr/bin/bpytop", line 2938, in _runner
    collector._collect()
  File "/usr/bin/bpytop", line 3775, in _collect
    cls.details = det.as_dict(attrs=attrs, ad_value="")
  File "/usr/lib/python3.9/site-packages/psutil/__init__.py", line 512, in as_dict
    raise ValueError("invalid attr name%s %s" % (
ValueError: invalid attr name 'io_counters'
01/10/21 (12:53:13) | WARNING: Exiting with errorcode (1). Runtime 0:01:05 

04/10/21 (15:21:21) | ERROR: division by zero
Traceback (most recent call last):
  File "/usr/bin/bpytop", line 5572, in main
    Box.calc_sizes()
  File "/usr/bin/bpytop", line 1685, in calc_sizes
    sub._calc_size() # type: ignore
  File "/usr/bin/bpytop", line 1822, in _calc_size
    cls.box_height = ceil(THREADS / cls.box_columns) + 4
ZeroDivisionError: division by zero
04/10/21 (15:21:21) | WARNING: Exiting with errorcode (1). Runtime 0:00:00 

04/10/21 (15:21:32) | ERROR: division by zero
Traceback (most recent call last):
  File "/usr/bin/bpytop", line 5572, in main
    Box.calc_sizes()
  File "/usr/bin/bpytop", line 1685, in calc_sizes
    sub._calc_size() # type: ignore
  File "/usr/bin/bpytop", line 1822, in _calc_size
    cls.box_height = ceil(THREADS / cls.box_columns) + 4
ZeroDivisionError: division by zero
04/10/21 (15:21:32) | WARNING: Exiting with errorcode (1). Runtime 0:00:00 

04/10/21 (15:25:58) | ERROR: division by zero
Traceback (most recent call last):
  File "/usr/bin/bpytop", line 5572, in main
    Box.calc_sizes()
  File "/usr/bin/bpytop", line 1685, in calc_sizes
    sub._calc_size() # type: ignore
  File "/usr/bin/bpytop", line 1822, in _calc_size
    cls.box_height = ceil(THREADS / cls.box_columns) + 4
ZeroDivisionError: division by zero
04/10/21 (15:25:58) | WARNING: Exiting with errorcode (1). Runtime 0:00:00 

04/10/21 (15:26:20) | ERROR: division by zero
Traceback (most recent call last):
  File "/usr/bin/bpytop", line 5572, in main
    Box.calc_sizes()
  File "/usr/bin/bpytop", line 1685, in calc_sizes
    sub._calc_size() # type: ignore
  File "/usr/bin/bpytop", line 1822, in _calc_size
    cls.box_height = ceil(THREADS / cls.box_columns) + 4
ZeroDivisionError: division by zero
04/10/21 (15:26:20) | WARNING: Exiting with errorcode (1). Runtime 0:00:00 

04/10/21 (15:52:37) | ERROR: division by zero
Traceback (most recent call last):
  File "/usr/bin/bpytop", line 5572, in main
    Box.calc_sizes()
  File "/usr/bin/bpytop", line 1685, in calc_sizes
    sub._calc_size() # type: ignore
  File "/usr/bin/bpytop", line 1822, in _calc_size
    cls.box_height = ceil(THREADS / cls.box_columns) + 4
ZeroDivisionError: division by zero
04/10/21 (15:52:37) | WARNING: Exiting with errorcode (1). Runtime 0:00:00 

06/10/21 (10:53:29) | ERROR: Data collection thread failed with exception: invalid attr name 'io_counters'
Traceback (most recent call last):
  File "/usr/bin/bpytop", line 2938, in _runner
    collector._collect()
  File "/usr/bin/bpytop", line 3775, in _collect
    cls.details = det.as_dict(attrs=attrs, ad_value="")
  File "/usr/lib/python3.9/site-packages/psutil/__init__.py", line 512, in as_dict
    raise ValueError("invalid attr name%s %s" % (
ValueError: invalid attr name 'io_counters'
06/10/21 (10:53:30) | WARNING: Exiting with errorcode (1). Runtime 0:00:10 

22/10/21 (15:41:45) | ERROR: Data collection thread failed with exception: integer division or modulo by zero
Traceback (most recent call last):
  File "/usr/bin/bpytop", line 2939, in _runner
    collector._draw()
  File "/usr/bin/bpytop", line 3971, in _draw
    ProcBox._draw_fg()
  File "/usr/bin/bpytop", line 2814, in _draw_fg
    val = ((v if v <= 100 else 100) + 100) - calc * 100 // cls.select_max
ZeroDivisionError: integer division or modulo by zero
22/10/21 (15:41:45) | WARNING: Exiting with errorcode (1). Runtime 0:00:00 

22/10/21 (15:41:47) | ERROR: Data collection thread failed with exception: integer division or modulo by zero
Traceback (most recent call last):
  File "/usr/bin/bpytop", line 2939, in _runner
    collector._draw()
  File "/usr/bin/bpytop", line 3971, in _draw
    ProcBox._draw_fg()
  File "/usr/bin/bpytop", line 2814, in _draw_fg
    val = ((v if v <= 100 else 100) + 100) - calc * 100 // cls.select_max
ZeroDivisionError: integer division or modulo by zero
22/10/21 (15:41:47) | WARNING: Exiting with errorcode (1). Runtime 0:00:00 

22/10/21 (15:41:48) | ERROR: Data collection thread failed with exception: integer division or modulo by zero
Traceback (most recent call last):
  File "/usr/bin/bpytop", line 2939, in _runner
    collector._draw()
  File "/usr/bin/bpytop", line 3971, in _draw
    ProcBox._draw_fg()
  File "/usr/bin/bpytop", line 2814, in _draw_fg
    val = ((v if v <= 100 else 100) + 100) - calc * 100 // cls.select_max
ZeroDivisionError: integer division or modulo by zero
22/10/21 (15:41:48) | WARNING: Exiting with errorcode (1). Runtime 0:00:00 

22/10/21 (15:41:49) | ERROR: Data collection thread failed with exception: integer division or modulo by zero
Traceback (most recent call last):
  File "/usr/bin/bpytop", line 2939, in _runner
    collector._draw()
  File "/usr/bin/bpytop", line 3971, in _draw
    ProcBox._draw_fg()
  File "/usr/bin/bpytop", line 2814, in _draw_fg
    val = ((v if v <= 100 else 100) + 100) - calc * 100 // cls.select_max
ZeroDivisionError: integer division or modulo by zero
22/10/21 (15:41:49) | WARNING: Exiting with errorcode (1). Runtime 0:00:00 

22/10/21 (15:41:50) | ERROR: Data collection thread failed with exception: integer division or modulo by zero
Traceback (most recent call last):
  File "/usr/bin/bpytop", line 2939, in _runner
    collector._draw()
  File "/usr/bin/bpytop", line 3971, in _draw
    ProcBox._draw_fg()
  File "/usr/bin/bpytop", line 2814, in _draw_fg
    val = ((v if v <= 100 else 100) + 100) - calc * 100 // cls.select_max
ZeroDivisionError: integer division or modulo by zero
22/10/21 (15:41:50) | WARNING: Exiting with errorcode (1). Runtime 0:00:00 

22/10/21 (15:41:50) | ERROR: Data collection thread failed with exception: integer division or modulo by zero
Traceback (most recent call last):
  File "/usr/bin/bpytop", line 2939, in _runner
    collector._draw()
  File "/usr/bin/bpytop", line 3971, in _draw
    ProcBox._draw_fg()
  File "/usr/bin/bpytop", line 2814, in _draw_fg
    val = ((v if v <= 100 else 100) + 100) - calc * 100 // cls.select_max
ZeroDivisionError: integer division or modulo by zero
22/10/21 (15:41:50) | WARNING: Exiting with errorcode (1). Runtime 0:00:00 

22/10/21 (15:41:51) | ERROR: Data collection thread failed with exception: integer division or modulo by zero
Traceback (most recent call last):
  File "/usr/bin/bpytop", line 2939, in _runner
    collector._draw()
  File "/usr/bin/bpytop", line 3971, in _draw
    ProcBox._draw_fg()
  File "/usr/bin/bpytop", line 2814, in _draw_fg
    val = ((v if v <= 100 else 100) + 100) - calc * 100 // cls.select_max
ZeroDivisionError: integer division or modulo by zero
22/10/21 (15:41:51) | WARNING: Exiting with errorcode (1). Runtime 0:00:00 

22/10/21 (15:41:51) | ERROR: Data collection thread failed with exception: integer division or modulo by zero
Traceback (most recent call last):
  File "/usr/bin/bpytop", line 2939, in _runner
    collector._draw()
  File "/usr/bin/bpytop", line 3971, in _draw
    ProcBox._draw_fg()
  File "/usr/bin/bpytop", line 2814, in _draw_fg
    val = ((v if v <= 100 else 100) + 100) - calc * 100 // cls.select_max
ZeroDivisionError: integer division or modulo by zero
22/10/21 (15:41:51) | WARNING: Exiting with errorcode (1). Runtime 0:00:00 

19/11/21 (15:19:00) | ERROR: Data collection thread failed with exception: list index out of range
Traceback (most recent call last):
  File "/usr/bin/bpytop", line 2939, in _runner
    collector._draw()
  File "/usr/bin/bpytop", line 3971, in _draw
    ProcBox._draw_fg()
  File "/usr/bin/bpytop", line 2815, in _draw_fg
    vals += [f'{THEME.gradient["proc_color" if val < 100 else "process"][val if val < 100 else val - 100]}']
IndexError: list index out of range
19/11/21 (15:19:00) | WARNING: Exiting with errorcode (1). Runtime 0:00:00 

22/11/21 (10:50:32) | ERROR: Data collection thread failed with exception: invalid attr name 'io_counters'
Traceback (most recent call last):
  File "/usr/bin/bpytop", line 2938, in _runner
    collector._collect()
  File "/usr/bin/bpytop", line 3775, in _collect
    cls.details = det.as_dict(attrs=attrs, ad_value="")
  File "/usr/lib/python3.9/site-packages/psutil/__init__.py", line 512, in as_dict
    raise ValueError("invalid attr name%s %s" % (
ValueError: invalid attr name 'io_counters'
22/11/21 (10:50:32) | WARNING: Exiting with errorcode (1). Runtime 0:01:22 

13/01/22 (15:22:51) | ERROR: Data collection thread failed with exception: invalid attr name 'io_counters'
Traceback (most recent call last):
  File "/usr/bin/bpytop", line 2958, in _runner
    collector._collect()
  File "/usr/bin/bpytop", line 3795, in _collect
    cls.details = det.as_dict(attrs=attrs, ad_value="")
  File "/usr/lib/python3.10/site-packages/psutil/__init__.py", line 518, in as_dict
    raise ValueError("invalid attr name%s %s" % (
ValueError: invalid attr name 'io_counters'
13/01/22 (15:22:52) | WARNING: Exiting with errorcode (1). Runtime 0:00:10 

07/02/22 (13:49:30) | ERROR: Data collection thread failed with exception: invalid attr name 'io_counters'
Traceback (most recent call last):
  File "/usr/bin/bpytop", line 2958, in _runner
    collector._collect()
  File "/usr/bin/bpytop", line 3795, in _collect
    cls.details = det.as_dict(attrs=attrs, ad_value="")
  File "/usr/lib/python3.10/site-packages/psutil/__init__.py", line 518, in as_dict
    raise ValueError("invalid attr name%s %s" % (
ValueError: invalid attr name 'io_counters'
07/02/22 (13:49:30) | WARNING: Exiting with errorcode (1). Runtime 0:00:14 

07/02/22 (14:02:24) | ERROR: Data collection thread failed with exception: invalid attr name 'io_counters'
Traceback (most recent call last):
  File "/usr/bin/bpytop", line 2958, in _runner
    collector._collect()
  File "/usr/bin/bpytop", line 3795, in _collect
    cls.details = det.as_dict(attrs=attrs, ad_value="")
  File "/usr/lib/python3.10/site-packages/psutil/__init__.py", line 518, in as_dict
    raise ValueError("invalid attr name%s %s" % (
ValueError: invalid attr name 'io_counters'
07/02/22 (14:02:25) | WARNING: Exiting with errorcode (1). Runtime 0:03:46 

07/02/22 (14:17:45) | ERROR: Data collection thread failed with exception: invalid attr name 'io_counters'
Traceback (most recent call last):
  File "/usr/bin/bpytop", line 2958, in _runner
    collector._collect()
  File "/usr/bin/bpytop", line 3795, in _collect
    cls.details = det.as_dict(attrs=attrs, ad_value="")
  File "/usr/lib/python3.10/site-packages/psutil/__init__.py", line 518, in as_dict
    raise ValueError("invalid attr name%s %s" % (
ValueError: invalid attr name 'io_counters'
07/02/22 (14:17:47) | WARNING: Exiting with errorcode (1). Runtime 0:01:05 

19/02/22 (13:53:16) | ERROR: Data collection thread failed with exception: invalid attr name 'io_counters'
Traceback (most recent call last):
  File "/usr/bin/bpytop", line 2958, in _runner
    collector._collect()
  File "/usr/bin/bpytop", line 3795, in _collect
    cls.details = det.as_dict(attrs=attrs, ad_value="")
  File "/usr/lib/python3.10/site-packages/psutil/__init__.py", line 518, in as_dict
    raise ValueError("invalid attr name%s %s" % (
ValueError: invalid attr name 'io_counters'
19/02/22 (13:53:17) | WARNING: Exiting with errorcode (1). Runtime 0:17:27 

19/02/22 (14:11:35) | ERROR: Data collection thread failed with exception: invalid attr name 'io_counters'
Traceback (most recent call last):
  File "/usr/bin/bpytop", line 2958, in _runner
    collector._collect()
  File "/usr/bin/bpytop", line 3795, in _collect
    cls.details = det.as_dict(attrs=attrs, ad_value="")
  File "/usr/lib/python3.10/site-packages/psutil/__init__.py", line 518, in as_dict
    raise ValueError("invalid attr name%s %s" % (
ValueError: invalid attr name 'io_counters'
19/02/22 (14:11:37) | WARNING: Exiting with errorcode (1). Runtime 0:01:16 

